<?xml version="1.0" encoding="utf-8"?>
<!-- This URDF was automatically created by SolidWorks to URDF Exporter! Originally created by Stephen Brawner (brawner@gmail.com) 
     Commit Version: 1.6.0-4-g7f85cfe  Build Version: 1.6.7995.38578
     For more information, please see http://wiki.ros.org/sw_urdf_exporter -->
<robot
  name="arm_urdf">

  <link name="world"/>
  <joint name="base_joint" type="fixed">
      <parent link="world"/>
      <child link="base_link"/>
      <origin rpy="0 0 0" xyz="0.0 0.0 0.87"/>
  </joint>

  <link
    name="base_link">
    <inertial>
      <origin
        xyz="-5.7174E-07 0.0045412 0.098906"
        rpy="0 0 0" />
      <mass
        value="3" />
      <inertia
        ixx="0.032295"
        ixy="5.8576E-06"
        ixz="-3.6591E-08"
        iyy="0.032303"
        iyz="1.0399E-07"
        izz="0.049257" />
    </inertial>
    <visual>
      <origin
        xyz="0 0 0"
        rpy="0 0 0" />
      <geometry>
        <mesh
          filename="package://configured_urdf/meshes/base_link.STL" />
      </geometry>
      <material
        name="">
        <color
          rgba="1 0.674 0.109 1" />
      </material>
    </visual>
    <collision>
      <origin
        xyz="0 0 0"
        rpy="0 0 0" />
      <geometry>
        <mesh
          filename="package://configured_urdf/meshes/base_link.STL" />
      </geometry>
    </collision>
  </link>
  <link
    name="link_1">
    <inertial>
      <origin
        xyz="-0.013855 7.5936E-05 0.086375"
        rpy="0 0 0" />
      <mass
        value="1.873" />
      <inertia
        ixx="0.00566351328283507"
        ixy="-1.04558937929122E-05"
        ixz="-6.48034055359616E-07"
        iyy="0.00839819660152376"
        iyz="6.49591458494556E-06"
        izz="0.00429596708244297" />
    </inertial>
    <visual>
      <origin
        xyz="0 0 0"
        rpy="0 0 0" />
      <geometry>
        <mesh
          filename="package://configured_urdf/meshes/link_1.STL" />
      </geometry>
      <material
        name="">
        <color
          rgba="0.803 0.498 0.196 1" />
      </material>
    </visual>
    <collision>
      <origin
        xyz="0 0 0"
        rpy="0 0 0" />
      <geometry>
        <mesh
          filename="package://configured_urdf/meshes/link_1.STL" />
      </geometry>
    </collision>
  </link>
  <joint
    name="joint_1"
    type="revolute">
    <origin
      xyz="0 0.00454 0.27675"
      rpy="0 0 0" />
    <parent
      link="base_link" />
    <child
      link="link_1" />
    <axis
      xyz="0 0 -1" />
    <limit
      lower="-3.14"
      upper="3.14"
      effort="100"
      velocity="2" />
  </joint>
  <link
    name="link_2">
    <inertial>
      <origin
        xyz="0.29593 0.00046382 0.12519"
        rpy="0 0 0" />
      <mass
        value="2.5" />
      <inertia
        ixx="0.00381425219473924"
        ixy="-6.14347545053114E-07"
        ixz="3.25630674096076E-07"
        iyy="0.00253644091656756"
        iyz="4.62685347382033E-05"
        izz="0.00455114275469431" />
    </inertial>
    <visual>
      <origin
        xyz="0 0 0"
        rpy="0 0 0" />
      <geometry>
        <mesh
          filename="package://configured_urdf/meshes/link_2.STL" />
      </geometry>
      <material
        name="">
        <color
          rgba="0.855 0.6274 0.4274 1" />
      </material>
    </visual>
    <collision>
      <origin
        xyz="0 0 0"
        rpy="0 0 0" />
      <geometry>
        <mesh
          filename="package://configured_urdf/meshes/link_2.STL" />
      </geometry>
    </collision>
  </link>
  <joint
    name="joint_2"
    type="revolute">
    <origin
      xyz="0 0 0.11125"
      rpy="0 -1.5708 0" />
    <parent
      link="link_1" />
    <child
      link="link_2" />
    <axis
      xyz="0 0 1" />
    <limit
      lower="-2.5"
      upper="2.5"
      effort="100"
      velocity="1" />
  </joint>
  <link
    name="link_3">
    <inertial>
      <origin
        xyz="0.32444 -6.8657E-07 0.039405"
        rpy="0 0 0" />
      <mass
        value="1" />
      <inertia
        ixx="0.00196021824270027"
        ixy="9.25458253531087E-09"
        ixz="0.00010306604826548"
        iyy="0.00515003950689768"
        iyz="2.37777893997033E-07"
        izz="0.00549377032977703" />
    </inertial>
    <visual>
      <origin
        xyz="0 0 0"
        rpy="0 0 0" />
      <geometry>
        <mesh
          filename="package://configured_urdf/meshes/link_3.STL" />
      </geometry>
      <material
        name="">
        <color
          rgba="0.8 0.33333 0 1" />
      </material>
    </visual>
    <collision>
      <origin
        xyz="0 0 0"
        rpy="0 0 0" />
      <geometry>
        <mesh
          filename="package://configured_urdf/meshes/link_3.STL" />
      </geometry>
    </collision>
  </link>
  <joint
    name="joint_3"
    type="revolute">
    <origin
      xyz="0.55067 0.0010554 0.059019"
      rpy="3.1416 0 0" />
    <parent
      link="link_2" />
    <child
      link="link_3" />
    <axis
      xyz="0 0 1" />
    <limit
      lower="-2.5"
      upper="2.5"
      effort="100"
      velocity="3" />
  </joint>
  <link
    name="link_4">
    <inertial>
      <origin
        xyz="1.3229E-08 -0.0050573 0.035081"
        rpy="0 0 0" />
      <mass
        value="1.744" />
      <inertia
        ixx="0.00249453144751075"
        ixy="7.73589000942063E-07"
        ixz="0.000170421488833695"
        iyy="0.00280473142887027"
        iyz="5.087762095777E-10"
        izz="0.00274584396628007" />
    </inertial>
    <visual>
      <origin
        xyz="0 0 0"
        rpy="0 0 0" />
      <geometry>
        <mesh
          filename="package://configured_urdf/meshes/link_4.STL" />
      </geometry>
      <material
        name="">
        <color
          rgba="0.9317 0.4549 0.3176 1" />
      </material>
    </visual>
    <collision>
      <origin
        xyz="0 0 0"
        rpy="0 0 0" />
      <geometry>
        <mesh
          filename="package://configured_urdf/meshes/link_4.STL" />
      </geometry>
    </collision>
  </link>
  <joint
    name="joint_4"
    type="revolute">
    <origin
      xyz="0.55 0 -0.10754"
      rpy="-3.1416 0 0" />
    <parent
      link="link_3" />
    <child
      link="link_4" />
    <axis
      xyz="0 0 -1" />
    <limit
      lower="-3.14"
      upper="3.14"
      effort="100"
      velocity="3" />
  </joint>
  <link
    name="link_5">
    <inertial>
      <origin
        xyz="-0.0036254 2.0253E-08 0.0394"
        rpy="0 0 0" />
      <mass
        value="1.5" />
      <inertia
        ixx="0.00202763520282033"
        ixy="-8.51201181339961E-08"
        ixz="-0.000105317069769619"
        iyy="0.00234849069953242"
        iyz="3.03954991529095E-10"
        izz="0.00214314421305717" />
    </inertial>
    <visual>
      <origin
        xyz="0 0 0"
        rpy="0 0 0" />
      <geometry>
        <mesh
          filename="package://configured_urdf/meshes/link_5.STL" />
      </geometry>
      <material
        name="">
        <color
          rgba="0.949 0.549 0.1568 1" />
      </material>
    </visual>
    <collision>
      <origin
        xyz="0 0 0"
        rpy="0 0 0" />
      <geometry>
        <mesh
          filename="package://configured_urdf/meshes/link_5.STL" />
      </geometry>
    </collision>
  </link>
  <joint
    name="joint_5"
    type="revolute">
    <origin
      xyz="0 -0.157 0.14"
      rpy="1.5708 0 0" />
    <parent
      link="link_4" />
    <child
      link="link_5" />
    <axis
      xyz="0 0 1" />
    <limit
      lower="-3.14"
      upper="3.14"
      effort="100"
      velocity="3" />
  </joint>
  <link
    name="link_6">
    <inertial>
      <origin
        xyz="-8.1852E-05 4.7642E-05 0.015002"
        rpy="0 0 0" />
      <mass
        value="1.7" />
      <inertia
        ixx="0.00129580720562651"
        ixy="-2.11975079631151E-06"
        ixz="-8.20914432830694E-07"
        iyy="0.00147763709203844"
        iyz="-1.21375457564458E-06"
        izz="0.00138719029183947" />
    </inertial>
    <visual>
      <origin
        xyz="0 0 0"
        rpy="0 0 0" />
      <geometry>
        <mesh
          filename="package://configured_urdf/meshes/link_6.STL" />
      </geometry>
      <material
        name="">
        <color
          rgba="1 0.498 0.3137 1" />
      </material>
    </visual>
    <collision>
      <origin
        xyz="0 0 0"
        rpy="0 0 0" />
      <geometry>
        <mesh
          filename="package://configured_urdf/meshes/link_6.STL" />
      </geometry>
    </collision>
  </link>
  <joint
    name="joint_6"
    type="revolute">
    <origin
      xyz="-0.157 0 0.14"
      rpy="-1.5708 0 1.5708" />
    <parent
      link="link_5" />
    <child
      link="link_6" />
    <axis
      xyz="0 0 -1" />
    <limit
      lower="-1.2"
      upper="4.2"
      effort="100"
      velocity="3" />
  </joint>

   <link
    name="right_gripper">
    <inertial>
      <origin
        xyz="0.013255 0.080275 0.00033066"
        rpy="0 0 0" />
      <mass
        value="0.028855" />
      <inertia
        ixx="1.2432E-05"
        ixy="1.8928E-07"
        ixz="3.263E-12"
        iyy="4.3852E-06"
        iyz="-7.5287E-12"
        izz="1.2567E-05" />
    </inertial>
    <visual>
      <origin
        xyz="0 0 0"
        rpy="0 0 0" />
      <geometry>
        <mesh
          filename="package://configured_urdf/meshes/right_gripper.STL" />
      </geometry>
      <material
        name="">
        <color
          rgba="0.8941 0.6078 0.0588 1" />
      </material>
    </visual>
    <collision>
      <origin
        xyz="0 0 0"
        rpy="0 0 0" />
      <geometry>
        <mesh
          filename="package://configured_urdf/meshes/right_gripper.STL" />
      </geometry>
    </collision>

    <dynamics damping="1" friction="1"/>
    
  </link>
  <joint
    name="right_ee_joint"
    type="revolute">
    <origin
      xyz="0.031487 2.5E-05 0.14715"
      rpy="1.5708 0 -3.1416" />
    <parent
      link="link_6" />
    <child
      link="right_gripper" />
    <axis
      xyz="0 0 -1" />
    <limit
      lower="-1"
      upper="0"
      effort="0.1"
      velocity="2" />
  </joint>
  <link
    name="left_gripper">
    <inertial>
      <origin
        xyz="-0.012568 0.080386 0.00028069"
        rpy="0 0 0" />
      <mass
        value="0.028855" />
      <inertia
        ixx="1.2428E-05"
        ixy="-2.5801E-07"
        ixz="3.3277E-12"
        iyy="4.389E-06"
        iyz="7.4999E-12"
        izz="1.2567E-05" />
    </inertial>
    <visual>
      <origin
        xyz="0 0 0"
        rpy="0 0 0" />
      <geometry>
        <mesh
          filename="package://configured_urdf/meshes/left_gripper.STL" />
      </geometry>
      <material
        name="">
        <color
          rgba="0.7529 0.2509 0 1" />
      </material>
    </visual>
    <collision>
      <origin
        xyz="0 0 0"
        rpy="0 0 0" />
      <geometry>
        <mesh
          filename="package://configured_urdf/meshes/left_gripper.STL" />
      </geometry>
    </collision>

    <dynamics damping="1" friction="1.0"/>
    
  </link>
  <joint
    name="left_ee_joint"
    type="revolute">
    <origin
      xyz="-0.031487 2.5E-05 0.14715"
      rpy="1.5708 0 3.1416" />
    <parent
      link="link_6" />
    <child
      link="left_gripper" />
    <axis
      xyz="0 0 -1" />
    <limit
      lower="0"
      upper="1"
      effort="0.1"
      velocity="2" />
  </joint>

  <transmission name="link_1_trans">
      <type>transmission_interface/SimpleTransmission</type>
      <joint name="joint_1">
          <hardwareInterface>hardware_interface/PositionJointInterface</hardwareInterface>
      </joint>
      <actuator name="link_1_motor">
          <hardwareInterface>hardware_interface/PositionJointInterface</hardwareInterface>
          <mechanicalReduction>1</mechanicalReduction>
      </actuator>
  </transmission>

  <transmission name="link_2_trans">
    <type>transmission_interface/SimpleTransmission</type>
    <joint name="joint_2">
        <hardwareInterface>hardware_interface/PositionJointInterface</hardwareInterface>
    </joint>
    <actuator name="link_2_motor">
        <hardwareInterface>hardware_interface/PositionJointInterface</hardwareInterface>
        <mechanicalReduction>1</mechanicalReduction>
    </actuator>
</transmission>

<transmission name="link_3_trans">
  <type>transmission_interface/SimpleTransmission</type>
  <joint name="joint_3">
      <hardwareInterface>hardware_interface/PositionJointInterface</hardwareInterface>
  </joint>
  <actuator name="link_3_motor">
      <hardwareInterface>hardware_interface/PositionJointInterface</hardwareInterface>
      <mechanicalReduction>1</mechanicalReduction>
  </actuator>
</transmission>

<transmission name="link_4_trans">
  <type>transmission_interface/SimpleTransmission</type>
  <joint name="joint_4">
      <hardwareInterface>hardware_interface/PositionJointInterface</hardwareInterface>
  </joint>
  <actuator name="link_4_motor">
      <hardwareInterface>hardware_interface/PositionJointInterface</hardwareInterface>
      <mechanicalReduction>1</mechanicalReduction>
  </actuator>
</transmission>

<transmission name="link_5_trans">
  <type>transmission_interface/SimpleTransmission</type>
  <joint name="joint_5">
      <hardwareInterface>hardware_interface/PositionJointInterface</hardwareInterface>
  </joint>
  <actuator name="link_5_motor">
      <hardwareInterface>hardware_interface/PositionJointInterface</hardwareInterface>
      <mechanicalReduction>1</mechanicalReduction>
  </actuator>
</transmission>

<transmission name="link_6_trans">
  <type>transmission_interface/SimpleTransmission</type>
  <joint name="joint_6">
      <hardwareInterface>hardware_interface/PositionJointInterface</hardwareInterface>
  </joint>
  <actuator name="link_6_motor">
      <hardwareInterface>hardware_interface/PositionJointInterface</hardwareInterface>
      <mechanicalReduction>1</mechanicalReduction>
  </actuator>
</transmission> 

<transmission name="link_7_trans">
  <type>transmission_interface/SimpleTransmission</type>
  <joint name="right_ee_joint">
      <hardwareInterface>hardware_interface/EffortJointInterface</hardwareInterface>
  </joint>
  <actuator name="link_7_motor">
      <hardwareInterface>hardware_interface/EffortJointInterface</hardwareInterface>
      <mechanicalReduction>1</mechanicalReduction>
  </actuator>
</transmission> 

<transmission name="link_8_trans">
  <type>transmission_interface/SimpleTransmission</type>
  <joint name="left_ee_joint">
      <hardwareInterface>hardware_interface/EffortJointInterface</hardwareInterface>
  </joint>
  <actuator name="link_8_motor">
      <hardwareInterface>hardware_interface/EffortJointInterface</hardwareInterface>
      <mechanicalReduction>1</mechanicalReduction>
  </actuator>
</transmission> 

  <gazebo>
    <plugin name="control" filename="libgazebo_ros_control.so">
        <robotNamespace>/</robotNamespace>
        <robotSimType>gazebo_ros_control/DefaultRobotHWSim</robotSimType>
    </plugin>
  </gazebo>


  <gazebo reference="link_1">
    <mu1>2</mu1>
    <mu2>2</mu2>
  </gazebo>

  <gazebo reference="link_2">
    <mu1>0.2</mu1>
    <mu2>0.2</mu2>
  </gazebo>

  <gazebo reference="link_3">
    <mu1>0.2</mu1>
    <mu2>0.2</mu2>
  </gazebo>

  <gazebo reference="link_4">
    <mu1>0.2</mu1>
    <mu2>0.2</mu2>
  </gazebo>

  <gazebo reference="link_5">
    <mu1>0.2</mu1>
    <mu2>0.2</mu2>
  </gazebo>

  <gazebo reference="link_6">
    <mu1>0.2</mu1>
    <mu2>0.2</mu2>
  </gazebo>

  <gazebo reference="right_gripper">
    <kp>1000000.0</kp>
    <kd>1.0</kd>
    <mu1>30.0</mu1>
    <mu2>30.0</mu2>
  </gazebo>

  <gazebo reference="left_gripper">
    <kp>1000000.0</kp>
    <kd>1.0</kd>
    <mu1>30.0</mu1>
    <mu2>30.0</mu2>
  </gazebo>

  <gazebo>
    <plugin name="gazebo_grasp_fix" filename="libgazebo_grasp_fix.so">
      <arm>
        <arm_name>/</arm_name>
        <palm_link>link_6</palm_link>
        <gripper_link>right_gripper</gripper_link>
        <gripper_link>left_gripper</gripper_link>
      </arm>
      <forces_angle_tolerance>90</forces_angle_tolerance>
      <update_rate>10</update_rate>
      <grip_count_threshold>3</grip_count_threshold>
      <max_grip_count>10</max_grip_count>
      <release_tolerance>0.004</release_tolerance>
      <disable_collisions_on_attach>false</disable_collisions_on_attach>
      <contact_topic>__default_topic__</contact_topic>
    </plugin> 
  </gazebo>


</robot>
